<?xml version="1.0"?>
<robot name="three_dof_arm">

    <!-- Base Footprint -->
    <link name="base_footprint">
    </link>

    <!-- Dummy Joint -->
    <joint name="base_to_arm_base_joint" type="fixed">
        <parent link="base_footprint"/>
        <child link="arm_base_link"/>
        <origin xyz="0 0 0.0" rpy="0 0 0"/>
    </joint>

    <!-- Base Link -->
    <link name="arm_base_link">
        <visual>
            <geometry>
                <cylinder radius="0.1" length="0.1"/>
            </geometry>
        </visual>
        <collision>
            <geometry>
                <cylinder radius="0.1" length="0.1"/>
            </geometry>     
        </collision>
        <inertial>
            <mass value="1.0"/>
            <origin xyz="0 0 0" rpy="0 0 0"/>
            <inertia ixx="0.0033" ixy="0.0" ixz="0.0" iyy="0.0033" iyz="0.0" izz="0.0050"/>
        </inertial>
    </link>

    <!-- First Link -->
    <link name="shoulder_link">
        <visual>
            <geometry>
                <cylinder radius="0.05" length="0.1"/>
            </geometry>
        </visual>
        <collision>
            <geometry>
                <cylinder radius="0.05" length="0.1"/>
            </geometry> 
        </collision>
        <inertial>
            <mass value="1.0"/>
            <origin xyz="0 0 0" rpy="0 0 0"/>
            <inertia ixx="0.000458" ixy="0.0" ixz="0.0" iyy="0.000458" iyz="0.0" izz="0.00125"/>
        </inertial>
    </link>

    <!-- First Joint -->
    <joint name="base_to_shoulder_joint" type="revolute">
        <parent link="arm_base_link"/>
        <child link="shoulder_link"/>
        <origin xyz="0 0 0.10" rpy="0 0 0"/>
        <axis xyz="0 0 1"/>
        <limit lower="-3.14" upper="3.14" effort="10" velocity="1"/>
    </joint>

    <!-- Second Link -->
    <link name="upper_arm_link">
        <visual>
            <geometry>
                <cylinder radius="0.05" length="0.1"/>
            </geometry>
        </visual>
        <collision>
            <geometry>
                <cylinder radius="0.05" length="0.1"/>
            </geometry>
        </collision>
        <inertial>
            <mass value="1.0"/>
            <origin xyz="0 0 0" rpy="0 0 0"/>
            <inertia ixx="0.000458" ixy="0.0" ixz="0.0" iyy="0.000458" iyz="0.0" izz="0.00125"/>
        </inertial>
    </link>

    <!-- Second Joint -->
    <joint name="shoulder_to_upper_arm_joint" type="revolute">
        <parent link="shoulder_link"/>
        <child link="upper_arm_link"/>
        <origin xyz="0 0 0.10" rpy="1.57 0 0"/>
        <axis xyz="0 0 1"/>
        <limit lower="-1.57" upper="1.57" effort="10" velocity="1"/>
    </joint>

    <!-- Third Link -->
    <link name="forearm_link">
        <visual>
            <geometry>
                <cylinder radius="0.05" length="0.3"/>
            </geometry>
        </visual>
        <collision>
            <geometry>
                <cylinder radius="0.05" length="0.3"/>
            </geometry>
        </collision>
        <inertial>
            <mass value="1.0"/>
            <origin xyz="0 0 0" rpy="0 0 0"/>
            <inertia ixx="0.00229" ixy="0.0" ixz="0.0" iyy="0.00229" iyz="0.0" izz="0.00125"/>
        </inertial>
    </link>

    <!-- Third Joint (Fixed) -->
    <joint name="upper_arm_to_forearm_joint" type="fixed">
        <parent link="upper_arm_link"/>
        <child link="forearm_link"/>
        <origin xyz="0 0.2 0" rpy="-1.57 0 0"/>
    </joint>

    <!-- Fourth Link -->
    <link name="wrist_link">
        <visual>
            <geometry>
                <cylinder radius="0.05" length="0.1"/>
            </geometry>
        </visual>
        <collision>
            <geometry>
                <cylinder radius="0.05" length="0.1"/>
            </geometry>
        </collision>
        <inertial>
            <mass value="1.0"/>
            <origin xyz="0 0 0" rpy="0 0 0"/>
            <inertia ixx="0.000458" ixy="0.0" ixz="0.0" iyy="0.000458" iyz="0.0" izz="0.00125"/>
        </inertial>
    </link>

    <!-- Fourth Joint -->
    <joint name="forearm_to_wrist_joint" type="revolute">
        <parent link="forearm_link"/>
        <child link="wrist_link"/>
        <origin xyz="0 0 0.2" rpy="1.57 0 0"/>
        <axis xyz="0 0 1"/>
        <limit lower="-1.57" upper="1.57" effort="10" velocity="1"/>
    </joint>

    <!-- End Effector -->
    <link name="end_effector_link">
        <visual>
            <geometry>
                <cylinder radius="0.05" length="0.2"/>
            </geometry>
        </visual>
        <collision>
            <geometry>
                <cylinder radius="0.05" length="0.2"/>
            </geometry>
        </collision>
        <inertial>
            <mass value="1.0"/>
            <origin xyz="0 0 0" rpy="0 0 0"/>
            <inertia ixx="0.000916" ixy="0.0" ixz="0.0" iyy="0.000916" iyz="0.0" izz="0.0025"/>
        </inertial>
    </link>
 
    <!-- End Effector Joint (Fixed) -->
    <joint name="wrist_to_end_effector_joint" type="fixed">
        <parent link="wrist_link"/>
        <child link="end_effector_link"/>
        <origin xyz="0 0.15 0" rpy="1.57 0 0"/>
    </joint>

</robot>
